2024-05-14 00:15:40,018 FILE: creds.py IN: create_new_token MESSAGE: Ошибка получения iam_token: HTTPConnectionPool(host='169.254.169.254', port=80): Max retries exceeded with url: /computeMetadata/v1/instance/service-accounts/default/token (Caused by NewConnectionError('<urllib3.connection.HTTPConnection object at 0x0000027304CA6940>: Failed to establish a new connection: [WinError 10065] Сделана попытка выполнить операцию на сокете для недоступного хоста'))
